Workbook

Sheet Инструкция
B2: Модель TCO (Total Cost of Ownership) — кейс «Africa Delivery», горизонт 5 лет
B4: Зачем этот файл
B5: Задача | C5: Оценить полную стоимость владения выбранным архитектурным вариантом на 5 лет и использовать цифры как аргумент в ADR №1 («Выбор архитектурного стиля»).
B6: Как использовать | C6: Заполни один и тот же шаблон для каждого рассматриваемого варианта (например: модульный монолит / SOA / микросервисы) — сравнивать нужно итоги, а не ощущения.
B8: Цветовая легенда
B9: Синий текст на жёлтом фоне | C9: Ячейки для заполнения. Только их и редактируем.
B10: Чёрный текст | C10: Формулы. Не трогаем — пересчитаются сами.
B11: Зелёный текст | C11: Ссылка на лист «Допущения».
B13: Порядок работы
B14: Шаг 1 | C14: Лист «Допущения» → блок 1: вбить драйверы бизнеса по годам (активные пользователи, число заказов, средний чек). Из них считается GMV.
B15: Шаг 2 | C15: Лист «Допущения» → блок 2: финансовые допущения (инфляция, рост ФОТ, ставка дисконтирования, резерв, целевой SLO).
B16: Шаг 3 | C16: Лист «TCO» → в колонке «База, $/год (Год 1)» указать затраты первого года по каждой статье. Лишние статьи оставить пустыми, свои — дописать в свободные строки.
B17: Шаг 4 | C17: Лист «TCO» → в колонке «Драйвер роста» выбрать из выпадающего списка, от чего растёт статья: фикс / инфляция / ФОТ / пользователи / заказы / GMV. Годы 2–5 посчитаются сами.
B18: Шаг 5 | C18: Посмотреть блок «Ключевые метрики» внизу листа «TCO»: итог за 5 лет, NPV, стоимость на заказ, проверку бюджета CFO ($9k/мес на облако).
B20: Что важно не забыть в этом кейсе
B21: Бюджет CFO | C21: $9 000/мес на облако на старте. Если Год 1 в блоке «Облачная инфраструктура» не проходит — это архитектурное решение, а не ошибка модели: опиши, что урезаешь.
B22: Цена простоя | C22: Инвестор оценивает минуту простоя в $12 000. Целевой SLO 99,99% = 52,6 мин/год ≈ $631k. Этот риск считается отдельным блоком — сравни его со стоимостью резервирования.
B23: Транзакционные расходы | C23: Комиссии M-Pesa / Flutterwave / Paystack, SMS и WhatsApp растут с GMV и числом заказов и на горизонте 5 лет обычно обгоняют инфраструктуру. Не забудь их — это типичная ошибка.
B24: Сравнение вариантов | C24: Транзакционные расходы (блок 3) почти одинаковы для любой архитектуры — это pass-through от оборота. Варианты архитектуры сравнивай по блокам 1, 2, 4 и 6.
B25: Разовые затраты | C25: Комплаенс-аудит NDPR/POPIA, пентест, миграция — если статья возникает не каждый год, просто перезапиши формулу в нужной ячейке года числом (и покрась в синий).
B26: Люди | C26: ФОТ команды — обычно самая крупная статья TCO. Микросервисы дешевле в масштабировании, но дороже в эксплуатации: это должно быть видно в цифрах, а не только в тексте ADR.
B28: Все числа в файле — примеры для демонстрации формата. Замени их своими оценками и укажи источник в колонке «Комментарий / источник».

Sheet Сравнение
B2: Сравнение вариантов архитектуры — сводка для ADR №1
B4: Показатель | C4: A — монолит | D4: B — сервисы | E4: C — вариант CTO | F4: Источник / комментарий
B5: Деплой-единиц | C5: 2 | D5: 9–10 | E5: 40–50 | F5: арт. 5 для C
B6: Облако и SaaS, $/мес в Год 1 | C6: 2550 | D6: 4150 | E6: 7720 | F6: лимит CFO $5 000/мес (арт. 6); для C — без разовой лицензии
B7: % лимита CFO | C7: 0.51 | D7: 0.83 | E7: 1.544
B8: Разовые лицензии, Год 1 | C8: 0 | D8: 0 | E8: 95000 | F8: Oracle EE, 2 процессора — прайс-лист
B9: Команда, FTE Год 1 | C9: 6 | D9: 9 | E9: 19–20 | F9: CFO: 6 контракторов, наём заморожен
B10: ФОТ, Год 1 | C10: 495000 | D10: 660000 | E10: 1260000 | F10: $60k разработчик, $70k SRE
B11: Целевой SLO | C11: 99,9% | D11: 99,95% | E11: 99,99%
B12: Простой, мин/год | C12: 525.6 | D12: 262.8 | E12: 52.56
B13: Потери от простоя, 5 лет | C13: 1611450 | D13: 805725 | E13: 161145 | F13: от выручки года, не по ставке $12k/мин
B14: TCO 5 лет, всего | C14: 47667383 | D14: 49092957 | E14: 54857487 | F14: включая транзакционные издержки
B15: Транзакционные издержки, 5 лет | C15: 40963575 | D15: 40963575 | E15: 40963575 | F15: одинаковы для всех вариантов — из сравнения исключаются
B16: TCO 5 лет, архитектурно-зависимая часть | C16: 6703808.1 | D16: 8129381.8 | E16: 13893912 | F16: по ней и сравниваем варианты
B17: Стоимость заказа, 5 лет | C17: 1.2511124 | D17: 1.2885291 | E17: 1.4398291 | F17: всего 38.1 млн заказов
B18: NPV затрат (ставка 20%) | C18: 27448857 | D18: 28418477 | E18: 32355636
B19: Готовность к 15.10.2026 | C19: с буфером ~2 недели | D19: сдвиг 3–5 недель | E19: II квартал 2027 | F19: своя логистика — 6 мес (оценка CTO)
B22: Стоимость ошибки (построили под 10 млн пользователей, пришло 50 тысяч)
B23: Статья | C23: Потери Года 1 при выборе C вместо A
B24: Облако | C24: 63240
B25: Лицензии и SaaS (в т. ч. Oracle) | C25: 93800
B26: ФОТ (20 FTE вместо 6) | C26: 765000
B27: Найм и миграция | C27: 80000
B28: Итого | C28: 1002040
B29: Обратная ошибка: построили A, пришло 10 млн — выделение сервисов | C29: 120000
B31: Асимметрия 8,4 : 1 — ошибиться в сторону простого решения в восемь раз дешевле, чем в сторону сложного.

Sheet Допущения
B2: Допущения модели TCO — Africa Delivery
B3: Заполняются только ячейки с жёлтой заливкой. Все числа ниже — пример, заменить своими.
B5: 1. Драйверы бизнеса — заполнить
B6: Показатель | C6: Год 1 | D6: Год 2 | E6: Год 3 | F6: Год 4 | G6: Год 5 | H6: Комментарий / источник
B7: Активные пользователи (на конец года) | C7: 150000 | D7: 600000 | E7: 1500000 | F7: 2500000 | G7: 3500000 | H7: Пилот: 100 продавцов, 5000 SKU; цель 1M+ к 12 мес (описание кейса)
B8: Число заказов в год | C8: 300000 | D8: 1800000 | E8: 6000000 | F8: 12000000 | G8: 18000000 | H8: Оценка архитектора от объёма пилота
B9: Средний чек (AOV), $ | C9: 25 | D9: 26 | E9: 27 | F9: 28 | G9: 29 | H9: Оценка студента по рынку (Jumia / Takealot)
B10: GMV, $ в год (расчёт) | C10: =C8*C9 | D10: 46800000 | E10: 162000000 | F10: 336000000 | G10: 522000000 | H10: Расчёт: заказы × средний чек
B12: 2. Финансовые допущения — заполнить
B13: Параметр | C13: Значение | H13: Комментарий / источник
B14: Инфляция затрат, % в год | C14: 0.08 | H14: Применяется к статьям с драйвером «инфляция»
B15: Рост ФОТ, % в год | C15: 0.12 | H15: Дефицит ИТ-специалистов на рынке — рост выше инфляции
B16: Ставка дисконтирования, % в год | C16: 0.2 | H16: Для расчёта NPV затрат. Стартап, высокий риск
B17: Резерв на непредвиденное (contingency), % | C17: 0.15 | H17: Надбавка к прямым затратам
B18: Бюджет CFO на облако, $/мес | C18: 5000 | H18: Письмо CFO (арт. 6): $5 000/мес на всё техническое — блоки 1 и 2, включая мониторинг и SaaS. $9 000 — цифра из презентации совету, разработке недоступна
B19: Стоимость минуты простоя, $ | C19: 12000 | H19: Оценка инвестора (арт. 1, 7). Проверка: $12k/мин x 525 600 мин = $6,3 млрд/год при GMV Года 1 $7,5 млн — это пиковая минута распродажи примерно Года 3, а не минута запуска
B20: Целевой SLO (доступность), % | C20: 0.999 | H20: SLO задаётся на листе каждого варианта: A — 99,9%, B — 99,95%, C — 99,99%
B21: Учитывать стоимость простоя в TCO (1 — да, 0 — нет) | C21: 0 | H21: 0 — методика инвестора отключена; потери считаются от выручки года (строка 53 на листах вариантов)
B23: 3. Индексы роста — расчёт, не редактировать
B24: Драйвер | C24: Год 1 | D24: Год 2 | E24: Год 3 | F24: Год 4 | G24: Год 5 | H24: Как считается
B25: фикс | C25: 1 | D25: 1 | E25: 1 | F25: 1 | G25: 1 | H25: Затраты не меняются по годам
B26: инфляция | C26: 1 | D26: =C26*(1+$C$14) | E26: =D26*(1+$C$14) | F26: =E26*(1+$C$14) | G26: =F26*(1+$C$14) | H26: Год N = Год N-1 × (1 + инфляция)
B27: ФОТ | C27: 1 | D27: =C27*(1+$C$15) | E27: =D27*(1+$C$15) | F27: =E27*(1+$C$15) | G27: =F27*(1+$C$15) | H27: Год N = Год N-1 × (1 + рост ФОТ)
B28: пользователи | C28: =C7/$C$7 | D28: =D7/$C$7 | E28: =E7/$C$7 | F28: =F7/$C$7 | G28: =G7/$C$7 | H28: Пропорционально числу активных пользователей
B29: заказы | C29: =C8/$C$8 | D29: =D8/$C$8 | E29: =E8/$C$8 | F29: =F8/$C$8 | G29: =G8/$C$8 | H29: Пропорционально числу заказов
B30: GMV | C30: =C10/$C$10 | D30: =D10/$C$10 | E30: =E10/$C$10 | F30: =F10/$C$10 | G30: =G10/$C$10 | H30: Пропорционально обороту
B32: Драйвер «пользователи» — упрощение: облачные расходы редко растут строго линейно (есть эффект масштаба и обратный эффект — рост нагрузки на БД). При желании введи свой драйвер отдельной строкой в таблице индексов.

Sheet TCO A — монолит
B2: TCO на 5 лет — Africa Delivery, вариант A — модульный монолит
B3: Целевой SLO варианта: 99.90%. Все числа — оценка архитектора, источники в колонке «Комментарий».
B5: Статья затрат | C5: Драйвер роста | D5: База, $/год (Год 1) | E5: Год 1 | F5: Год 2 | G5: Год 3 | H5: Год 4 | I5: Год 5 | J5: Итого 5 лет | K5: Доля | L5: Комментарий / источник
B6: БЛОК 1. Облачная инфраструктура (OpEx)
B7: Compute: ноды / контейнеры | C7: пользователи | D7: 4200 | E7: 4200 | F7: 16800 | G7: 42000 | H7: 70000 | I7: 98000 | J7: 231000 | L7: 2 деплой-единицы (app + worker), 2-4 реплики
B8: Управляемая БД (PostgreSQL + реплика) | C8: пользователи | D8: 3600 | E8: 3600 | F8: 14400 | G8: 36000 | H8: 60000 | I8: 84000 | J8: 198000 | L8: один инстанс, схема на модуль
B9: Хранилище объектов и резервные копии | C9: пользователи | D9: 600 | E9: 600 | F9: 2400 | G9: 6000 | H9: 10000 | I9: 14000 | J9: 33000 | L9: фото 5000 SKU
B10: CDN и исходящий трафик | C10: пользователи | D10: 1800 | E10: 1800 | F10: 7200 | G10: 18000 | H10: 30000 | I10: 42000 | J10: 99000 | L10: 3G, WebP, 80-90% отдаётся из кеша
B11: Резервный регион / DR | C11: пользователи | D11: 1200 | E11: 1200 | F11: 4800 | G11: 12000 | H11: 20000 | I11: 28000 | J11: 66000 | L11: бэкапы в соседний регион, RPO — минуты
B12: Локальное размещение данных (NDPR, Нигерия) | C12: инфляция | D12: 4800 | E12: 4800 | F12: 5184 | G12: 5598.72 | H12: 6046.62 | I12: 6530.35 | J12: 28159.68 | L12: площадка под ПД — см. Task4
B13: Сеть, балансировщик, DNS, WAF | C13: инфляция | D13: 3000 | E13: 3000 | F13: 3240 | G13: 3499.2 | H13: 3779.14 | I13: 4081.47 | J13: 17599.8
B15: Итого по блоку | E15: 19200 | F15: 54024 | G15: 123097.92 | H15: 199825.75 | I15: 276611.81 | J15: 672759.49 | K15: =IFERROR(J15/$J$51,0)
B17: БЛОК 2. Лицензии, SaaS и инструменты
B18: Observability (метрики, логи, трейсинг) | C18: пользователи | D18: 2400 | E18: 2400 | F18: 9600 | G18: 24000 | H18: 40000 | I18: 56000 | J18: 132000 | L18: один рантайм — минимальный объём
B19: CI/CD, репозиторий, артефакты | C19: инфляция | D19: 1200 | E19: 1200 | F19: 1296 | G19: 1399.68 | H19: 1511.65 | I19: 1632.59 | J19: 7039.92
B20: Безопасность: секреты, сканеры | C20: пользователи | D20: 2400 | E20: 2400 | F20: 9600 | G20: 24000 | H20: 40000 | I20: 56000 | J20: 132000
B21: WhatsApp Business API (подписка) | C21: инфляция | D21: 3000 | E21: 3000 | F21: 3240 | G21: 3499.2 | H21: 3779.14 | I21: 4081.47 | J21: 17599.8 | L21: канал для продавцов
B22: Прочее ПО и подписки | C22: инфляция | D22: 2400 | E22: 2400 | F22: 2592 | G22: 2799.36 | H22: 3023.31 | I22: 3265.17 | J22: 14079.84
B24: Итого по блоку | E24: 11400 | F24: 26328 | G24: 55698.24 | H24: 88314.1 | I24: 120979.23 | J24: 302719.57 | K24: =IFERROR(J24/$J$51,0)
B26: БЛОК 3. Транзакционные расходы (Buy / Partner)
B27: Комиссии платёжных провайдеров | C27: GMV | D27: 187500 | E27: 187500 | F27: 1170000 | G27: 4050000 | H27: 8400000 | I27: 13050000 | J27: 26857500 | L27: 2,5% GMV — верхняя граница CFO (арт. 6)
B28: SMS-уведомления | C28: заказы | D28: 30000 | E28: 30000 | F28: 180000 | G28: 600000 | H28: 1200000 | I28: 1800000 | J28: 3810000 | L28: ~2,5 SMS на заказ x $0,04
B29: WhatsApp-сообщения (за диалог) | C29: заказы | D29: 9000 | E29: 9000 | F29: 54000 | G29: 180000 | H29: 360000 | I29: 540000 | J29: 1143000 | L29: тариф Meta за conversation
B30: Логистика: интеграции и комиссии партнёров | C30: заказы | D30: 30000 | E30: 30000 | F30: 180000 | G30: 600000 | H30: 1200000 | I30: 1800000 | J30: 3810000 | L30: Sendbox (Нигерия), Sendy (Кения)
B32: Итого по блоку | E32: 256500 | F32: 1584000 | G32: 5430000 | H32: 11160000 | I32: 17190000 | J32: 35620500 | K32: =IFERROR(J32/$J$51,0)
B34: БЛОК 4. Команда (ФОТ)
B35: Разработка (4 FTE x $60k) | C35: ФОТ | D35: 240000 | E35: 240000 | F35: 268800 | G35: 301056 | H35: 337182.72 | I35: 377644.65 | J35: 1524683.4 | L35: в рамках 6 контракторов CFO
B36: DevOps / SRE (1 FTE x $70k) | C36: ФОТ | D36: 70000 | E36: 70000 | F36: 78400 | G36: 87808 | H36: 98344.96 | I36: 110146.36 | J36: 444699.32
B37: Поддержка и дежурства (0,5 FTE) | C37: ФОТ | D37: 35000 | E37: 35000 | F37: 39200 | G37: 43904 | H37: 49172.48 | I37: 55073.18 | J37: 222349.66 | L37: дежурят разработчики
B38: Архитектура и менеджмент | C38: ФОТ | D38: 150000 | E38: 150000 | F38: 168000 | G38: 188160 | H38: 210739.2 | I38: 236027.9 | J38: 952927.1 | L38: SA + CTO
B40: Итого по блоку | E40: 495000 | F40: 554400 | G40: 620928 | H40: 695439.36 | I40: 778892.08 | J40: 3144659.4 | K40: =IFERROR(J40/$J$51,0)
B42: БЛОК 5. Разовые затраты и комплаенс
B43: Юридический и комплаенс-аудит (NDPR, POPIA, KICA) | C43: фикс | D43: 25000 | E43: 25000 | F43: 0 | G43: 25000 | H43: 0 | I43: 0 | J43: 50000 | L43: Год 1 — Нигерия и Кения, Год 3 — ЮАР
B44: Пентест и аудит безопасности | C44: инфляция | D44: 15000 | E44: 15000 | F44: 16200 | G44: 17496 | H44: 18895.68 | I44: 20407.33 | J44: 87999.01 | L44: ежегодно
B45: Миграция данных и интеграции при запуске | C45: фикс | D45: 20000 | E45: 20000 | F45: 0 | G45: 0 | H45: 0 | I45: 0 | J45: 20000
B46: Обучение команды и найм | C46: фикс | D46: 30000 | E46: 30000 | F46: 0 | G46: 0 | H46: 0 | I46: 0 | J46: 30000
B47: Выделение сервисов из монолита (переход к B) | C47: фикс | D47: 120000 | E47: 0 | F47: 0 | G47: 120000 | H47: 0 | I47: 0 | J47: 120000 | L47: 3 инженера x 4 мес — цена будущего перехода учтена здесь
B48: Итого по блоку | E48: 90000 | F48: 16200 | G48: 162496 | H48: 18895.68 | I48: 20407.33 | J48: 307999.01 | K48: =IFERROR(J48/$J$51,0)
B50: Резерв на непредвиденное (contingency) | E50: =(E15+E24+E32+E40+E48)*'Допущения'!$C$17 | F50: =(F15+F24+F32+F40+F48)*'Допущения'!$C$17 | G50: =(G15+G24+G32+G40+G48)*'Допущения'!$C$17 | H50: =(H15+H24+H32+H40+H48)*'Допущения'!$C$17 | I50: =(I15+I24+I32+I40+I48)*'Допущения'!$C$17 | J50: 6007295.6 | L50: Расчёт: сумма блоков 1–5 × ставка резерва с листа «Допущения»
B51: ИТОГО прямые затраты (TCO без учёта простоев) | E51: 1002915 | F51: 2570194.8 | G51: 7351053.2 | H51: 13986846 | I51: 21144924 | J51: 46055933
...

Sheet TCO B — сервисы
B2: TCO на 5 лет — Africa Delivery, вариант B — сервисы вокруг заказа
B3: Целевой SLO варианта: 99.95%. Все числа — оценка архитектора, источники в колонке «Комментарий».
B5: Статья затрат | C5: Драйвер роста | D5: База, $/год (Год 1) | E5: Год 1 | F5: Год 2 | G5: Год 3 | H5: Год 4 | I5: Год 5 | J5: Итого 5 лет | K5: Доля | L5: Комментарий / источник
B6: БЛОК 1. Облачная инфраструктура (OpEx)
B7: Compute: ноды / контейнеры | C7: пользователи | D7: 6600 | E7: 6600 | F7: 26400 | G7: 66000 | H7: 110000 | I7: 154000 | J7: 363000 | L7: 9-10 сервисов x 2 реплики (CN.SEL.01)
B8: Управляемые БД (2 инстанса PostgreSQL) | C8: пользователи | D8: 7200 | E8: 7200 | F8: 28800 | G8: 72000 | H8: 120000 | I8: 168000 | J8: 396000 | L8: БД на сервис
B9: Очереди / стриминг (managed Kafka) | C9: пользователи | D9: 4200 | E9: 4200 | F9: 16800 | G9: 42000 | H9: 70000 | I9: 98000 | J9: 231000 | L9: шина событий
B10: Аналитическое хранилище (ClickHouse) | C10: пользователи | D10: 3000 | E10: 3000 | F10: 12000 | G10: 30000 | H10: 50000 | I10: 70000 | J10: 165000 | L10: дашборд с обновлением раз в минуту
B11: Хранилище объектов и CDN | C11: пользователи | D11: 2400 | E11: 2400 | F11: 9600 | G11: 24000 | H11: 40000 | I11: 56000 | J11: 132000
B12: Резервный регион / DR | C12: пользователи | D12: 1800 | E12: 1800 | F12: 7200 | G12: 18000 | H12: 30000 | I12: 42000 | J12: 99000
B13: Локальное размещение данных (NDPR, Нигерия) | C13: инфляция | D13: 4800 | E13: 4800 | F13: 5184 | G13: 5598.72 | H13: 6046.62 | I13: 6530.35 | J13: 28159.68
B14: Сеть, балансировщик, DNS, WAF | C14: инфляция | D14: 3600 | E14: 3600 | F14: 3888 | G14: 4199.04 | H14: 4534.96 | I14: 4897.76 | J14: 21119.76
B15: Итого по блоку | E15: 33600 | F15: 109872 | G15: 261797.76 | H15: 430581.58 | I15: 599428.11 | J15: 1435279.4 | K15: =IFERROR(J15/$J$51,0)
B17: БЛОК 2. Лицензии, SaaS и инструменты
B18: Observability (метрики, логи, трейсинг) | C18: пользователи | D18: 6000 | E18: 6000 | F18: 24000 | G18: 60000 | H18: 100000 | I18: 140000 | J18: 330000 | L18: 10 сервисов: больше метрик и трассировка
B19: CI/CD, репозиторий, артефакты | C19: инфляция | D19: 1800 | E19: 1800 | F19: 1944 | G19: 2099.52 | H19: 2267.48 | I19: 2448.88 | J19: 10559.88 | L19: пайплайн на сервис
B20: Безопасность: секреты, сканеры | C20: пользователи | D20: 3000 | E20: 3000 | F20: 12000 | G20: 30000 | H20: 50000 | I20: 70000 | J20: 165000
B21: WhatsApp Business API (подписка) | C21: инфляция | D21: 3000 | E21: 3000 | F21: 3240 | G21: 3499.2 | H21: 3779.14 | I21: 4081.47 | J21: 17599.8
B22: Прочее ПО и подписки | C22: инфляция | D22: 2400 | E22: 2400 | F22: 2592 | G22: 2799.36 | H22: 3023.31 | I22: 3265.17 | J22: 14079.84
B24: Итого по блоку | E24: 16200 | F24: 43776 | G24: 98398.08 | H24: 159069.93 | I24: 219795.52 | J24: 537239.53 | K24: =IFERROR(J24/$J$51,0)
B26: БЛОК 3. Транзакционные расходы (Buy / Partner)
B27: Комиссии платёжных провайдеров | C27: GMV | D27: 187500 | E27: 187500 | F27: 1170000 | G27: 4050000 | H27: 8400000 | I27: 13050000 | J27: 26857500 | L27: 2,5% GMV — верхняя граница CFO (арт. 6)
B28: SMS-уведомления | C28: заказы | D28: 30000 | E28: 30000 | F28: 180000 | G28: 600000 | H28: 1200000 | I28: 1800000 | J28: 3810000 | L28: ~2,5 SMS на заказ x $0,04
B29: WhatsApp-сообщения (за диалог) | C29: заказы | D29: 9000 | E29: 9000 | F29: 54000 | G29: 180000 | H29: 360000 | I29: 540000 | J29: 1143000 | L29: тариф Meta за conversation
B30: Логистика: интеграции и комиссии партнёров | C30: заказы | D30: 30000 | E30: 30000 | F30: 180000 | G30: 600000 | H30: 1200000 | I30: 1800000 | J30: 3810000 | L30: Sendbox (Нигерия), Sendy (Кения)
B32: Итого по блоку | E32: 256500 | F32: 1584000 | G32: 5430000 | H32: 11160000 | I32: 17190000 | J32: 35620500 | K32: =IFERROR(J32/$J$51,0)
B34: БЛОК 4. Команда (ФОТ)
B35: Разработка (5 FTE x $60k) | C35: ФОТ | D35: 300000 | E35: 300000 | F35: 336000 | G35: 376320 | H35: 421478.4 | I35: 472055.81 | J35: 1905854.2 | L35: +1 к имеющимся шести
B36: DevOps / SRE (2 FTE x $70k) | C36: ФОТ | D36: 140000 | E36: 140000 | F36: 156800 | G36: 175616 | H36: 196689.92 | I36: 220292.71 | J36: 889398.63 | L36: K8s, Kafka, ClickHouse
B37: Поддержка и дежурства (1 FTE) | C37: ФОТ | D37: 70000 | E37: 70000 | F37: 78400 | G37: 87808 | H37: 98344.96 | I37: 110146.36 | J37: 444699.32
B38: Архитектура и менеджмент | C38: ФОТ | D38: 150000 | E38: 150000 | F38: 168000 | G38: 188160 | H38: 210739.2 | I38: 236027.9 | J38: 952927.1
B40: Итого по блоку | E40: 660000 | F40: 739200 | G40: 827904 | H40: 927252.48 | I40: 1038522.8 | J40: 4192879.3 | K40: =IFERROR(J40/$J$51,0)
B42: БЛОК 5. Разовые затраты и комплаенс
B43: Юридический и комплаенс-аудит (NDPR, POPIA, KICA) | C43: фикс | D43: 25000 | E43: 25000 | F43: 0 | G43: 25000 | H43: 0 | I43: 0 | J43: 50000 | L43: Год 1 — Нигерия и Кения, Год 3 — ЮАР
B44: Пентест и аудит безопасности | C44: инфляция | D44: 15000 | E44: 15000 | F44: 16200 | G44: 17496 | H44: 18895.68 | I44: 20407.33 | J44: 87999.01 | L44: ежегодно
B45: Миграция данных и интеграции при запуске | C45: фикс | D45: 20000 | E45: 20000 | F45: 0 | G45: 0 | H45: 0 | I45: 0 | J45: 20000
B46: Обучение команды и найм | C46: фикс | D46: 45000 | E46: 45000 | F46: 0 | G46: 0 | H46: 0 | I46: 0 | J46: 45000 | L46: +3 человека
B48: Итого по блоку | E48: 105000 | F48: 16200 | G48: 42496 | H48: 18895.68 | I48: 20407.33 | J48: 202999.01 | K48: =IFERROR(J48/$J$51,0)
B50: Резерв на непредвиденное (contingency) | E50: =(E15+E24+E32+E40+E48)*'Допущения'!$C$17 | F50: =(F15+F24+F32+F40+F48)*'Допущения'!$C$17 | G50: =(G15+G24+G32+G40+G48)*'Допущения'!$C$17 | H50: =(H15+H24+H32+H40+H48)*'Допущения'!$C$17 | I50: =(I15+I24+I32+I40+I48)*'Допущения'!$C$17 | J50: 6298334.6 | L50: Расчёт: сумма блоков 1–5 × ставка резерва с листа «Допущения»
B51: ИТОГО прямые затраты (TCO без учёта простоев) | E51: 1231995 | F51: 2867005.2 | G51: 7659685.2 | H51: 14600170 | I51: 21928377 | J51: 48287232
...

Sheet TCO C — вариант CTO
B2: TCO на 5 лет — Africa Delivery, вариант C — вариант CTO (арт. 5)
B3: Целевой SLO варианта: 99.99%. Все числа — оценка архитектора, источники в колонке «Комментарий».
B5: Статья затрат | C5: Драйвер роста | D5: База, $/год (Год 1) | E5: Год 1 | F5: Год 2 | G5: Год 3 | H5: Год 4 | I5: Год 5 | J5: Итого 5 лет | K5: Доля | L5: Комментарий / источник
B6: БЛОК 1. Облачная инфраструктура (OpEx)
B7: Compute: 2 региона active-active + Istio | C7: пользователи | D7: 21120 | E7: 21120 | F7: 84480 | G7: 211200 | H7: 352000 | I7: 492800 | J7: 1161600 | L7: 40-50 сервисов x 2 реплики x 2 региона, +15% на sidecar
B8: Ноды под Oracle (self-hosted, 2 региона) | C8: пользователи | D8: 17520 | E8: 17520 | F8: 70080 | G8: 175200 | H8: 292000 | I8: 408800 | J8: 963600 | L8: r6i.2xlarge x2
B9: Kafka self-hosted (6 брокеров) | C9: пользователи | D9: 7200 | E9: 7200 | F9: 28800 | G9: 72000 | H9: 120000 | I9: 168000 | J9: 396000 | L9: «никаких managed» — арт. 5
B10: Self-hosted стек наблюдаемости | C10: пользователи | D10: 4800 | E10: 4800 | F10: 19200 | G10: 48000 | H10: 80000 | I10: 112000 | J10: 264000 | L10: Prometheus, Loki, Jaeger, Grafana
B11: Control plane Kubernetes (2 кластера) | C11: фикс | D11: 1800 | E11: 1800 | F11: 1800 | G11: 1800 | H11: 1800 | I11: 1800 | J11: 9000
B12: Межрегиональный трафик, DR, RPO=0 | C12: пользователи | D12: 3600 | E12: 3600 | F12: 14400 | G12: 36000 | H12: 60000 | I12: 84000 | J12: 198000 | L12: синхронная репликация
B13: On-prem кластер в Нигерии | C13: инфляция | D13: 24000 | E13: 24000 | F13: 25920 | G13: 27993.6 | H13: 30233.09 | I13: 32651.74 | J13: 140798.42 | L13: колокация + железо в помесячном пересчёте; CFO запрещает capex
B14: Хранилище объектов и CDN | C14: пользователи | D14: 2400 | E14: 2400 | F14: 9600 | G14: 24000 | H14: 40000 | I14: 56000 | J14: 132000
B15: Итого по блоку | E15: 82440 | F15: 254280 | G15: 596193.6 | H15: 976033.09 | I15: 1356051.7 | J15: 3264998.4 | K15: =IFERROR(J15/$J$51,0)
B17: БЛОК 2. Лицензии, SaaS и инструменты
B18: Лицензия Oracle EE (2 процессора) | C18: фикс | D18: 95000 | E18: 95000 | F18: 0 | G18: 0 | H18: 0 | I18: 0 | J18: 95000 | L18: прайс-лист Oracle; CFO: лицензии за ядро — отказ (арт. 6)
B19: Поддержка Oracle (22% в год) | C19: инфляция | D19: 20900 | E19: 0 | F19: 22572 | G19: 24377.76 | H19: 26327.98 | I19: 28434.22 | J19: 101711.96
B20: CI/CD, репозиторий, артефакты | C20: инфляция | D20: 1800 | E20: 1800 | F20: 1944 | G20: 2099.52 | H20: 2267.48 | I20: 2448.88 | J20: 10559.88 | L20: GitOps, 40-50 пайплайнов
B21: Безопасность: секреты, сканеры | C21: пользователи | D21: 3000 | E21: 3000 | F21: 12000 | G21: 30000 | H21: 50000 | I21: 70000 | J21: 165000
B22: WhatsApp Business API (подписка) | C22: инфляция | D22: 3000 | E22: 3000 | F22: 3240 | G22: 3499.2 | H22: 3779.14 | I22: 4081.47 | J22: 17599.8
B23: Прочее ПО и подписки | C23: инфляция | D23: 2400 | E23: 2400 | F23: 2592 | G23: 2799.36 | H23: 3023.31 | I23: 3265.17 | J23: 14079.84
B24: Итого по блоку | E24: 105200 | F24: 42348 | G24: 62775.84 | H24: 85397.91 | I24: 108229.74 | J24: 403951.49 | K24: =IFERROR(J24/$J$51,0)
B26: БЛОК 3. Транзакционные расходы (Buy / Partner)
B27: Комиссии платёжных провайдеров | C27: GMV | D27: 187500 | E27: 187500 | F27: 1170000 | G27: 4050000 | H27: 8400000 | I27: 13050000 | J27: 26857500 | L27: 2,5% GMV — верхняя граница CFO (арт. 6)
B28: SMS-уведомления | C28: заказы | D28: 30000 | E28: 30000 | F28: 180000 | G28: 600000 | H28: 1200000 | I28: 1800000 | J28: 3810000 | L28: ~2,5 SMS на заказ x $0,04
B29: WhatsApp-сообщения (за диалог) | C29: заказы | D29: 9000 | E29: 9000 | F29: 54000 | G29: 180000 | H29: 360000 | I29: 540000 | J29: 1143000 | L29: тариф Meta за conversation
B30: Логистика: интеграции и комиссии партнёров | C30: заказы | D30: 30000 | E30: 30000 | F30: 180000 | G30: 600000 | H30: 1200000 | I30: 1800000 | J30: 3810000 | L30: Sendbox (Нигерия), Sendy (Кения)
B32: Итого по блоку | E32: 256500 | F32: 1584000 | G32: 5430000 | H32: 11160000 | I32: 17190000 | J32: 35620500 | K32: =IFERROR(J32/$J$51,0)
B34: БЛОК 4. Команда (ФОТ)
B35: Разработка (10 FTE x $60k) | C35: ФОТ | D35: 600000 | E35: 600000 | F35: 672000 | G35: 752640 | H35: 842956.8 | I35: 944111.62 | J35: 3811708.4 | L35: вкл. 4 инженера на свой логистический движок (6 мес)
B36: DevOps / SRE (4 FTE x $70k) | C36: ФОТ | D36: 280000 | E36: 280000 | F36: 313600 | G36: 351232 | H36: 393379.84 | I36: 440585.42 | J36: 1778797.3 | L36: 3 кластера, service mesh, self-hosted stateful
B37: Поддержка и дежурства 24/7 (3 FTE) | C37: ФОТ | D37: 180000 | E37: 180000 | F37: 201600 | G37: 225792 | H37: 252887.04 | I37: 283233.48 | J37: 1143512.5 | L37: требование 99,99%
B38: Архитектура и менеджмент | C38: ФОТ | D38: 200000 | E38: 200000 | F38: 224000 | G38: 250880 | H38: 280985.6 | I38: 314703.87 | J38: 1270569.5
B40: Итого по блоку | E40: 1260000 | F40: 1411200 | G40: 1580544 | H40: 1770209.3 | I40: 1982634.4 | J40: 8004587.7 | K40: =IFERROR(J40/$J$51,0)
B42: БЛОК 5. Разовые затраты и комплаенс
B43: Юридический и комплаенс-аудит (NDPR, POPIA, KICA) | C43: фикс | D43: 25000 | E43: 25000 | F43: 0 | G43: 25000 | H43: 0 | I43: 0 | J43: 50000 | L43: Год 1 — Нигерия и Кения, Год 3 — ЮАР
B44: Пентест и аудит безопасности | C44: инфляция | D44: 15000 | E44: 15000 | F44: 16200 | G44: 17496 | H44: 18895.68 | I44: 20407.33 | J44: 87999.01 | L44: ежегодно
B45: Миграция данных и интеграции при запуске | C45: фикс | D45: 40000 | E45: 40000 | F45: 0 | G45: 0 | H45: 0 | I45: 0 | J45: 40000
B46: Обучение команды и найм | C46: фикс | D46: 90000 | E46: 90000 | F46: 0 | G46: 0 | H46: 0 | I46: 0 | J46: 90000 | L46: +13-14 человек при замороженном найме
B48: Итого по блоку | E48: 170000 | F48: 16200 | G48: 42496 | H48: 18895.68 | I48: 20407.33 | J48: 267999.01 | K48: =IFERROR(J48/$J$51,0)
B50: Резерв на непредвиденное (contingency) | E50: =(E15+E24+E32+E40+E48)*'Допущения'!$C$17 | F50: =(F15+F24+F32+F40+F48)*'Допущения'!$C$17 | G50: =(G15+G24+G32+G40+G48)*'Допущения'!$C$17 | H50: =(H15+H24+H32+H40+H48)*'Допущения'!$C$17 | I50: =(I15+I24+I32+I40+I48)*'Допущения'!$C$17 | J50: 7134305.5 | L50: Расчёт: сумма блоков 1–5 × ставка резерва с листа «Допущения»
...
